<?xml version='1.0' encoding="UTF-8"?>
<sdf version="1.7">

    <world name="cube_world">
                
		<!-- Light source -->
	    <light type="directional" name="sun">
            <cast_shadows>true</cast_shadows>
            <pose>0 0 10 0 0 0</pose>
            <diffuse>0.8 0.8 0.8 1</diffuse>
            <specular>0.2 0.2 0.2 1</specular>
        </light>

    <!-- Ground Plane Model -->
	<model name="ground_plane">
            <static>true</static>
            <link name="link">
                <collision name="collision">
                    <geometry>
                    <plane>
                        <normal>0 0 1</normal>
                        <size>100 100</size>
                    </plane>
                    </geometry>
                </collision>
                <visual name="visual">
                    <geometry>
                    <plane>
                        <normal>0 0 1</normal>
                        <size>100 100</size>
                    </plane>
                    </geometry>
                <material>
                    <script>
                        <uri>file://media/materials/scripts/gazebo.material</uri>
                        <name>Gazebo/Grey</name>
                    </script>
                </material>
                </visual>
            </link>
    </model>


    <!-- Model that includes box and the reaction wheel at the center -->
	<model name="robot">
		<link name="box">
            <inertial>
                <pose>0 0 0.5 0 0 0</pose>
                <mass>1</mass>
                <inertia>
                   <ixx>0.1</ixx>
                   <ixy>0</ixy>
                   <ixz>0</ixz>
                   <iyy>0.1</iyy>
                   <iyz>0</iyz>
                   <izz>0.1</izz>
                </inertia>
            </inertial>
        <collision name="box_collision">
            <pose>0 0 0.5 0 0 0</pose>
            <geometry>
                <box>
                   <size>1 1 1</size> 
                </box>
            </geometry>
        </collision>
        <visual name="box_visual">
            <pose>0 0 0.5 0 0 0</pose>
            <geometry>
               <box>
                   <size>1 1 1</size> 
               </box>
            </geometry>
            <material>
                <ambient>0.8 0 0 1</ambient>
                <diffuse>0.8 0 0 1</diffuse>
                <specular>0.8 0 0 1</specular>
            </material>
        </visual>
    </link>
<joint name="disc_joint" type="revolute">
	<pose relative_to="box">0 0 0.5 0 0 0</pose>
		<parent>box</parent>
		<child>disc_link</child>
		<axis>
			<xyz>0 1 0</xyz>
			<limit>
			    <effort>1000</effort>
				<velocity>100</velocity>
			</limit>
			<dynamics>
			    <spring_reference>0</spring_reference>
				<spring_stiffness>0</spring_stiffness>
			</dynamics>
		</axis>
</joint>
<link name="disc_link">
	<pose relative_to="disc_joint">0 0 0 0 0 0</pose>
		<inertial>
			<pose>0 0 0 0 0 0</pose>
			<mass>1</mass>
			<inertia>
				<ixx>0.1</ixx>
				<ixy>0</ixy>
				<ixz>0</ixz>
				<iyy>0.1</iyy>
				<iyz>0</iyz>
				<izz>0.1</izz>
			</inertia>
		</inertial>
		<collision name="disc_collision">
			<pose>0 0 0 0 0 0</pose>
			<geometry>
				<cylinder>
					<length>0.1</length>
					<radius>0.4</radius>
				</cylinder>
			</geometry>
		</collision>
		<visual name="disc_visual">
			<pose>0 0 0 1.570796326794896 0 0</pose>
				<geometry>
					<cylinder>
						<length>0.1</length>
						<radius>0.4</radius>
					</cylinder>
				</geometry>
		    <material>
				<diffuse>1 0.625 0 1</diffuse>
				<ambient>1 0.625 0 1</ambient>
			</material>
		</visual>
</link>
		
<plugin filename="libignition-gazebo-joint-controller-system.so"
	name="ignition::gazebo::systems::JointController">
	<joint_name>disc_joint</joint_name>
	<topic>cmd_vel</topic>
</plugin>
</model>

    <!-- Including all the plugins that are required -->
    <plugin
	    filename="libignition-gazebo-physics-system.so"
	    name="ignition::gazebo::systems::Physics">
	</plugin>
	
	<plugin
	    filename="libignition-gazebo-user-commands-system.so"
	    name="ignition::gazebo::systems::UserCommands">
	</plugin>
	
	<plugin
        filename="libignition-gazebo-scene-broadcaster-system.so"
	    name="ignition::gazebo::systems::SceneBroadcaster">
	</plugin>

	<!-- Code to move the box in forward direction -->
	<plugin filename="libignition-gazebo-triggered-publisher-system.so"
		name="ignition::gazebo::systems::TriggeredPublisher">
		<input type="ignition.msgs.Int32" topic="/keyboard/keypress">
			<match field="data">87</match> 
		</input>
		<output type="ignition.msgs.Double" topic="/cmd_vel">
			data: 25.0
		</output>
	</plugin>

	<!-- Code to move the box in backward direction -->
	<plugin filename="libignition-gazebo-triggered-publisher-system.so"
		name="ignition::gazebo::systems::TriggeredPublisher">
		<input type="ignition.msgs.Int32" topic="/keyboard/keypress">
				<match field="data">83</match> 
		</input>
		<output type="ignition.msgs.Double" topic="/cmd_vel">
			data: -25.0
		</output>
	</plugin>
		
	<!-- Code to stop the wheel motion -->
	<plugin filename="libignition-gazebo-triggered-publisher-system.so"
	    name="ignition::gazebo::systems::TriggeredPublisher">
		<input type="ignition.msgs.Int32" topic="/keyboard/keypress">
			<match field="data">66</match> <!-- ASCII code for 'b' -->
		</input>
		<output type="ignition.msgs.Double" topic="/cmd_vel">
			data: 0.0
		</output>
    </plugin>

</world>
</sdf>
